Workbook

Sheet T01-2024
A1: VPA - SẢN LƯỢNG CONTAINER (TEU) - THÁNG 1 NĂM 2024 / 2023
A3: KHU VỰC / Cảng | B3: Năm 2023 | C3: 1T 2023 | D3: 1T 2024 | E3: THÁNG 1-2024 | O3: 1T (2024 / 2023)
E4: CỘNG | F4: Nhập Ngoại | G4: Xuất Ngoại | H4: Nhập nội | I4: Xuất nội | J4: Trung chuyển | K4: 20' | L4: Rỗng | M4: Lạnh | N4: GN qua sà lan
A6: MIỀN BẮC | B6: =SUM(B7:B18) -> 4518182 | C6: =SUM(C7:C18) -> 295945 | D6: =SUM(D8:D18) -> 451236 | E6: =SUM(E8:E18) -> 451236 | F6: =SUM(F8:F17) -> 184406 | G6: =SUM(G8:G17) -> 182272 | H6: =SUM(H8:H17) -> 34386 | I6: =SUM(I8:I17) -> 37691 | O6: =+D6/C6 -> 1.5247293
A7: Quang Ninh
A8: Cái Lân (CICT) | E8: =F8+G8+H8+I8+J8 -> 0
A9: Hai Phong (Chùa Vẽ+Tân Vũ) | B9: =715133+126685+111732+106510+95851+111311 -> 1267222 | C9: 82758 | D9: =108077 -> 108077 | E9: =SUM(F9:J9) -> 108077 | F9: 38493 | G9: 37849 | H9: 14834 | I9: 16901 | O9: =+D9/C9 -> 1.3059402
A10: HICT (Lạch Huyện, HP) | B10: 1272859 | C10: 86070 | D10: =148719 -> 148719 | E10: =SUM(F10:J10) -> 148719 | F10: 73486 | G10: 75233 | K10: =9953+8358 -> 18311 | L10: =2805+1881 -> 4686 | O10: =+D10/C10 -> 1.7278843
A11: Đoạn Xá | E11: =SUM(F11:J11) -> 0
A12: Đình vũ | B12: 491959 | C12: 36966 | D12: =39231 -> 39231 | E12: =SUM(F12:J12) -> 39231 | F12: 19340 | G12: 18849 | H12: 648 | I12: 394 | K12: =6080+2677+153+102 -> 9012 | L12: =26+2912+9 -> 2947 | O12: =+D12/C12 -> 1.0612725
A13: Nam Hải Đình Vũ | B13: 149160 | C13: 41503 | D13: 0 | E13: =SUM(F13:J13) -> 0
A14: Nam Đình Vũ | B14: =27700+42263+60649+60306+68982+89333+103549+96251+80177+83538+83985+100491 -> 897224 | C14: 27700 | D14: =107401 -> 107401 | E14: =SUM(F14:J14) -> 107401 | F14: 50060 | G14: 47718 | H14: 4470 | I14: 5153 | K14: =10956+8425+755+989 -> 21125 | L14: =1010+4403+61+58 -> 5532 | M14: =4682 -> 4682 | N14: 891 | O14: =+D14/C14 -> 3.8772924
A15: Tân Cảng 128 Hải Phòng | B15: =6147+7479+7850+9613+8350+10297+8331+8950+9929+9191+7491+7125 -> 100753 | C15: 6147 | D15: =5818 -> 5818 | E15: =SUM(F15:J15) -> 5818 | H15: 2779 | I15: 3039 | K15: 1864 | L15: =128+1843 -> 1971 | O15: =+D15/C15 -> 0.94647796
A16: Transvina | B16: =540+350 -> 890 | C16: 0 | D16: 436 | E16: 436
A17: PTSC Đình Vũ | B17: =14801+21013+19343+20052+25339+15490+23521+25450+24091+25115+25902+30182 -> 270299 | C17: 14801 | D17: =29509 -> 29509 | E17: =SUM(F17:J17) -> 29509 | F17: 3027 | G17: 2623 | H17: 11655 | I17: 12204 | K17: =945+407+3282+3089 -> 7723 | L17: =406+23+253 -> 682 | O17: =+D17/C17 -> 1.9937166
A18: VIMC Đình Vũ | B18: 67816 | C18: 0 | D18: 12045 | E18: 12045
A19: Vip Green Port (*) | B19: 633659 | C19: 47086 | D19: 57024 | E19: 57024 | O19: =+D19/C19 -> 1.2110606
A20: Green Port (*) | B20: 255481 | C20: 20295 | D20: 24857 | E20: 24857 | O20: =+D20/C20 -> 1.2247844
A21: Mipec (*) | B21: 92242 | C21: 15841 | D21: 4324 | E21: 4324 | O21: =+D21/C21 -> 0.27296257
A22: Hải An (*) | B22: 400078 | C22: 25414 | D22: 36183 | E22: 36183 | O22: =+D22/C22 -> 1.4237428
A23: TC 189 Hải Phòng (*) | B23: 171077 | C23: 13130 | D23: 14645 | E23: 14645 | O23: =+D23/C23 -> 1.1153846
A24: Nam Hải Dình Vũ (*) | B24: 270677 | C24: 41503 | D24: 22071 | E24: 22071 | O24: =+D24/C24 -> 0.53179288
A26: MIỀN TRUNG | B26: =SUM(B27:B30) -> 860026 | C26: =60154 -> 60154 | D26: =SUM(D27:D30) -> 93571 | E26: =SUM(E27:E30) -> 93571 | F26: =SUM(F27:F30) -> 36560 | G26: =SUM(G27:G30) -> 37251 | H26: =SUM(H27:H30) -> 13619 | I26: =SUM(I27:I30) -> 6141 | J26: =SUM(J27:J30) -> 0 | K26: =SUM(K27:K30) -> 14887 | L26: =SUM(L27:L30) -> 2813 | N26: =SUM(N27:N30) -> 0 | O26: =+D26/C26 -> 1.5555242
A27: Nghe Tinh | B27: =30481+3346 -> 33827 | C27: 2482 | D27: 6576 | E27: =SUM(F27:J27) -> 6576 | F27: 1932 | G27: 2256 | H27: =696+1176 -> 1872 | I27: =514+2 -> 516 | O27: =+D27/C27 -> 2.6494762
A28: Da Nang | B28: 675254 | C28: 42268 | D28: =64505 -> 64505 | E28: =SUM(F28:J28) -> 64505 | F28: 26657 | G28: 24991 | H28: 7349 | I28: 5508 | K28: =5262+5685+1790+503 -> 13240 | L28: =979+288+219 -> 1486 | O28: =+D28/C28 -> 1.5260954
A29: Quy Nhon | B29: =120488+12239+18218 -> 150945 | C29: 15404 | D29: =22490 -> 22490 | E29: =SUM(F29:J29) -> 22490 | F29: 7971 | G29: 10004 | H29: 4398 | I29: 117 | K29: =401+1205+41 -> 1647 | L29: =820+3+436+68 -> 1327 | O29: =+D29/C29 -> 1.4600104
A30: Cam Ranh | B30: 0 | D30: 0 | E30: =SUM(F30:J30) -> 0
A32: TP HCM | B32: =SUM(B33:B43) -> 8314054 | C32: =559851 -> 559851 | D32: =SUM(D33:D43) -> 775273 | E32: =SUM(E33:E43) -> 775273 | F32: =SUM(F33:F43) -> 291934 | G32: =SUM(G33:G43) -> 262156 | H32: =SUM(H33:H43) -> 106822 | I32: =SUM(I33:I43) -> 112238 | J32: =SUM(J33:J43) -> 2123 | K32: =SUM(K33:K43) -> 161941 | ... N32: =SUM(N33:N43) -> 63835 | O32: =+D32/C32 -> 1.3847845
A33: Binh Duong | B33: =439746+58130+61049 -> 558925 | C33: 39360 | D33: =67666 -> 67666 | E33: =SUM(F33:J33) -> 67666 | H33: 23881 | I33: 43785 | K33: =24+1809 -> 1833 | L33: =1221 -> 1221 | O33: =+D33/C33 -> 1.7191565
A34: Đồng Nai | B34: =506252+63971 -> 570223 | C34: 32272 | D34: =58796 -> 58796 | E34: =SUM(F34:J34) -> 58796 | H34: 11346 | I34: 47450 | K34: 1886 | L34: =11140+12 -> 11152 | N34: 58796 | O34: =+D34/C34 -> 1.8218889
A35: ITC- CORP | B35: =42017+51282+45948+47390+55304+49234+45680+47437+43911+34616+30188+41910 -> 534917 | C35: 42017 | D35: =43919 -> 43919 | E35: =SUM(F35:J35) -> 43919 | F35: 13854 | G35: 22333 | H35: 2841 | I35: 2768 | J35: 2123 | K35: =2577+5338+567+423+86 -> 8991 | L35: =343+17+58+31+41 -> 490 | N35: 3133 | O35: =+D35/C35 -> 1.0452674
A36: Cảng Sai Gòn | B36: =154869+18461+17185+18184+22072 -> 230771 | C36: 9329 | D36: =20214 -> 20214 | E36: =SUM(G36:H36) -> 20214 | G36: 10023 | H36: 10191 | K36: =677+588 -> 1265 | L36: 42 | O36: =+D36/C36 -> 2.1667917
A37: Ben Nghe | B37: =50925+32855+32535+28886+28236+30552+33558+32390+29858+33841+31383 -> 365019 | C37: 23096 | D37: =36191 -> 36191 | E37: =SUM(F37:J37) -> 36191 | H37: 18661 | I37: 17530 | K37: =414+366 -> 780 | M37: 406 | N37: 563 | O37: =+D37/C37 -> 1.5669813
A38: Tan Cang - Hiệp Phước | B38: =5696+3958+5815+9110+7468+13154+12856+16704+16494+13524+11707+13991 -> 130477 | C38: 5696 | D38: 12008 | E38: =SUM(F38:J38) -> 12008 | F38: 2972 | G38: 9036 | K38: 5158 | L38: =103+2944 -> 3047 | N38: 22 | O38: =+D38/C38 -> 2.1081461
A39: Tan Cang - Cat Lai | B39: =372397+393542+480876+438506+433683+444706+469051+460647+432596+460939+470477+474708 -> 5332128 | C39: 372397 | D39: =492323 -> 492323 | E39: =SUM(F39:J39) -> 492323 | F39: 272540 | G39: 219783 | K39: =71459+69689 -> 141148 | L39: =7525+5664 -> 13189 | O39: =+D39/C39 -> 1.322038
A40: VICT | B40: =32440+39588+48102+43548+41412+40968+51704+51435+55440+57617+45700+41689 -> 549643 | C40: 32440 | D40: =41444 -> 41444 | E40: =SUM(F40:J40) -> 41444 | F40: 2287 | H40: 39157 | O40: =+D40/C40 -> 1.2775586
A41: SPCT | B41: =SUM(C41:G41) -> 0 | C41: =SUM(D41:H41) -> 0 | E41: =SUM(F41:J41) -> 0
A42: Lotus | B42: =2388+2166+2181+2143+2735+2159+2232+3124+2401+2891+2264+3229 -> 29913 | C42: 2388 | D42: =1591 -> 1591 | E42: =SUM(F42:J42) -> 1591 | F42: 21 | G42: 120 | H42: 745 | I42: 705 | K42: 661 | L42: =21+212+90 -> 323 | N42: 200 | O42: =+D42/C42 -> 0.66624791
A43: Phuoc Long ICD | B43: 12038 | C43: 856 | D43: =1121 -> 1121 | E43: =SUM(F43:J43) -> 1121 | F43: 260 | G43: 861 | K43: 219 | L43: =216 -> 216 | N43: 1121 | O43: =+D43/C43 -> 1.3095794
A45: BR-VT | B45: =SUM(B46:B53) -> 4797590 | C45: =SUM(C46:C53) -> 307532 | D45: =SUM(D46:D53) -> 469512 | E45: =SUM(E46:E53) -> 469512 | F45: =SUM(F46:F53) -> 207190 | G45: =SUM(G46:G53) -> 229771 | H45: =SUM(H46:H53) -> 5268 | I45: =SUM(I46:I53) -> 3932 | ... N45: =SUM(N46:N53) -> 48129 | O45: =+D45/C45 -> 1.5267094
...

Sheet T02-2024
A1: VPA - SẢN LƯỢNG CONTAINER (TEU) - THÁNG 2 NĂM 2024 / 2023
A3: KHU VỰC / Cảng | B3: Năm 2023 | C3: 2T 2023 | D3: 2T 2024 | E3: THÁNG 2-2024 | O3: 2T (2024 / 2023)
E4: CỘNG | F4: Nhập Ngoại | G4: Xuất Ngoại | H4: Nhập nội | I4: Xuất nội | J4: Trung chuyển | K4: 20' | L4: Rỗng | M4: Lạnh | N4: GN qua sà lan
A6: MIỀN BẮC | B6: =SUM(B8:B18) -> 4518182 | C6: 572810 | D6: =SUM(D8:D18) -> 773065 | E6: =SUM(E8:E18) -> 322275 | F6: =SUM(F8:F17) -> 133130 | G6: =SUM(G8:G17) -> 141368 | H6: =SUM(H8:H17) -> 21438 | I6: =SUM(I8:I17) -> 21098 | O6: =+D6/C6 -> 1.3496011
A7: Quang Ninh
A8: Cái Lân (CICT) | E8: =F8+G8+H8+I8+J8 -> 0
A9: Hai Phong (Chùa Vẽ+Tân Vũ) | B9: =715133+126685+111732+106510+95851+111311 -> 1267222 | C9: 173850 | D9: =108077+85467 -> 193544 | E9: =F9+G9+H9+I9+J9 -> 85467 | F9: 31542 | G9: 34414 | H9: 10675 | I9: 8836 | O9: =+D9/C9 -> 1.1132816
A10: HICT (Lạch Huyện, HP) | B10: 1272859 | C10: 140074 | D10: =148719+103732 -> 252451 | E10: =F10+G10+H10+I10+J10 -> 103742 | F10: 49479 | G10: 54263 | K10: =6349+5682 -> 12031 | L10: =1182+901 -> 2083 | O10: =+D10/C10 -> 1.8022688
A11: Đoạn Xá | E11: =F11+G11+H11+I11+J11 -> 0
A12: Đình vũ | B12: 491959 | C12: 73578 | D12: =39231+38035 -> 77266 | E12: =F12+G12+H12+I12+J12 -> 38035 | F12: 18602 | G12: 18991 | H12: 217 | I12: 225 | K12: =5281+3131+100+85 -> 8597 | L12: =103+2470+19 -> 2592 | O12: =+D12/C12 -> 1.0501237
A13: Nam Hải Đình Vũ | B13: 149160 | C13: 65905 | D13: 0 | E13: =F13+G13+H13+I13+J13 -> 0
A14: Nam Đình Vũ | B14: =27700+42263+60649+60306+68982+89333+103549+96251+80177+83538+83985+100491 -> 897224 | C14: 69963 | D14: =107401+71667 -> 179068 | E14: =F14+G14+H14+I14+J14 -> 71667 | F14: 32713 | G14: 32947 | H14: 2623 | I14: 3384 | K14: =7496+6249+531+631 -> 14907 | L14: =265+1958+4+19 -> 2246 | N14: 493 | O14: =+D14/C14 -> 2.5594671
A15: Tân Cảng 128 Hải Phòng | B15: =6147+7479+7850+9613+8350+10297+8331+8950+9929+9191+7491+7125 -> 100753 | C15: 13626 | D15: =5818+3471 -> 9289 | E15: =F15+G15+H15+I15+J15 -> 3471 | H15: 1710 | I15: 1761 | K15: =424+247 -> 671 | L15: =40+252 -> 292 | O15: =+D15/C15 -> 0.68171143
A16: Transvina | B16: =540+350 -> 890 | C16: 436 | E16: =F16+G16+H16+I16+J16 -> 0
A17: PTSC Đình Vũ | B17: =14801+21013+19343+20052+25339+15490+23521+25450+24091+25115+25902+30182 -> 270299 | C17: 35814 | D17: =29509+14652 -> 44161 | E17: =F17+G17+H17+I17+J17 -> 14652 | F17: 794 | G17: 753 | H17: 6213 | I17: 6892 | K17: 4430 | L17: =335+44+707 -> 1086 | O17: =+D17/C17 -> 1.2330653
A18: VIMC Đình Vũ | B18: 67816 | C18: 0 | D18: =12045+5241 -> 17286 | E18: 5241
A19: Vip Green Port (*) | B19: 633659 | C19: 92860 | D19: 98758 | E19: 41734 | O19: =+D19/C19 -> 1.063515
A20: Green Port (*) | B20: 255481 | C20: 51923 | D20: 42497 | E20: 17640 | O20: =+D20/C20 -> 0.81846195
A21: Mipec (*) | B21: 92242 | C21: 24141 | D21: 8659 | E21: 4335 | O21: =+D21/C21 -> 0.3586844
A22: Hải An (*) | B22: 400078 | C22: 51923 | D22: 66690 | E22: 30507 | O22: =+D22/C22 -> 1.2844019
A23: TC 189 Hải Phòng (*) | B23: 171077 | C23: 25312 | D23: 26704 | E23: 12059 | O23: =+D23/C23 -> 1.0549937
A24: Nam Hải Dình Vũ (*) | B24: 270677 | C24: 65905 | D24: 31758 | E24: 9654 | O24: =+D24/C24 -> 0.48187543
A26: MIỀN TRUNG | B26: =SUM(B27:B30) -> 860026 | C26: 117905 | D26: =SUM(D27:D30) -> 153345 | E26: =SUM(E27:E30) -> 62162 | F26: =SUM(F27:F30) -> 20480 | G26: =SUM(G27:G30) -> 26786 | H26: =SUM(H27:H30) -> 8624 | I26: =SUM(I27:I30) -> 6272 | J26: =SUM(J27:J30) -> 0 | K26: =SUM(K27:K30) -> 9799 | L26: =SUM(L27:L30) -> 2552 | N26: =SUM(N27:N30) -> 2189 | O26: =+D26/C26 -> 1.300581
A27: Nghe Tinh | B27: =30481+3346 -> 33827 | C27: 5142 | D27: =4188+2189 -> 6377 | E27: =F27+G27+H27+I27+J27 -> 2189 | F27: 0 | G27: 0 | H27: 1180 | I27: 1009 | K27: =308+517 -> 825 | L27: =256+0 -> 256 | N27: 2189 | O27: =+D27/C27 -> 1.2401789
A28: Da Nang | B28: 675254 | C28: 87125 | D28: =64505+48073 -> 112578 | E28: =F28+G28+H28+I28+J28 -> 48073 | F28: 17209 | G28: 20201 | H28: 5473 | I28: 5190 | K28: =3134+3355+1112+318 -> 7919 | L28: =623+998+318 -> 1939 | O28: =+D28/C28 -> 1.2921435
A29: Quy Nhon | B29: =120488+12239+18218 -> 150945 | C29: 25638 | D29: =22490+11900 -> 34390 | E29: =F29+G29+H29+I29+J29 -> 11900 | F29: 3271 | G29: 6585 | H29: 1971 | I29: 73 | K29: =197+734+86+38 -> 1055 | L29: =306+1+31+19 -> 357 | O29: =+D29/C29 -> 1.3413683
A30: Cam Ranh | B30: 0 | C30: 0 | E30: =F30+G30+H30+I30+J30 -> 0
A32: TP HCM | B32: =SUM(B33:B43) -> 8314054 | C32: 1154786 | D32: =SUM(D33:D43) -> 1350534 | E32: =SUM(E33:E43) -> 575261 | F32: =SUM(F33:F43) -> 229451 | G32: =SUM(G33:G43) -> 186400 | H32: =SUM(H33:H43) -> 70832 | I32: =SUM(I33:I43) -> 86161 | J32: =SUM(J33:J43) -> 2417 | K32: =SUM(K33:K43) -> 142911 | ... N32: =SUM(N33:N43) -> 97566 | O32: =+D32/C32 -> 1.1695102
A33: Binh Duong | B33: =439746+58130+61049 -> 558925 | C33: 70773 | D33: =67666+51377 -> 119043 | E33: =F33+G33+H33+I33+J33 -> 51377 | H33: 17573 | I33: 33804 | K33: =17+1532 -> 1549 | L33: =670 -> 670 | N33: 51377 | O33: =+D33/C33 -> 1.6820398
A34: Đồng Nai | B34: =506252+63971 -> 570223 | C34: 62510 | D34: =58796+40986 -> 99782 | E34: =F34+G34+H34+I34+J34 -> 40986 | H34: 9517 | I34: 31469 | K34: 2134 | L34: =9344+75 -> 9419 | N34: 40986 | O34: =+D34/C34 -> 1.5962566
A35: ITC- CORP | B35: =42017+51282+45948+47390+55304+49234+45680+47437+43911+34616+30188+41910 -> 534917 | C35: 93299 | D35: =43919+38655 -> 82574 | E35: =F35+G35+H35+I35+J35 -> 38655 | F35: 11899 | G35: 16407 | H35: 3015 | I35: 4917 | J35: 2417 | K35: 7717 | L35: =4189+547+418+791+2009 -> 7954 | N35: 3162 | O35: =+D35/C35 -> 0.885047
A36: Cảng Sai Gòn | B36: =154869+18461+17185+18184+22072 -> 230771 | C36: 23143 | D36: =20214+11681 -> 31895 | E36: =F36+G36+H36+I36+J36 -> 11681 | G36: 49 | H36: 5876 | I36: 5756 | K36: =0+1300+1330 -> 2630 | L36: =49+570+394 -> 1013 | M36: 86 | O36: =+D36/C36 -> 1.3781705
A37: Ben Nghe | B37: =50925+32855+32535+28886+28236+30552+33558+32390+29858+33841+31383 -> 365019 | C37: 50925 | D37: =36191+20920 -> 57111 | E37: =F37+G37+H37+I37+J37 -> 20920 | H37: 10705 | I37: 10215 | K37: =3340+3369 -> 6709 | L37: =93+160 -> 253 | N37: 563 | O37: =+D37/C37 -> 1.1214728
A38: Tan Cang - Hiệp Phước | B38: =5696+3958+5815+9110+7468+13154+12856+16704+16494+13524+11707+13991 -> 130477 | C38: 9654 | D38: =12008+9467 -> 21475 | E38: =F38+G38+H38+I38+J38 -> 9467 | F38: 2925 | G38: 6542 | K38: 3511 | L38: =940+3628 -> 4568 | O38: =+D38/C38 -> 2.2244665
A39: Tan Cang - Cat Lai | B39: =372397+393542+480876+438506+433683+444706+469051+460647+432596+460939+470477+474708 -> 5332128 | C39: 765939 | D39: =492323+373517 -> 865840 | E39: =F39+G39+H39+I39+J39 -> 373517 | F39: 211405 | G39: 162112 | K39: 118089 | L39: =32428+12695 -> 45123 | O39: =+D39/C39 -> 1.1304294
A40: VICT | B40: =32440+39588+48102+43548+41412+40968+51704+51435+55440+57617+45700+41689 -> 549643 | C40: 72028 | D40: =41444+27037 -> 68481 | E40: =F40+G40+H40+I40+J40 -> 27037 | F40: 2891 | H40: 24146 | O40: =+D40/C40 -> 0.95075526
A41: SPCT | B41: =SUM(C41:G41) -> 0 | C41: 0 | E41: =F41+G41+H41+I41+J41 -> 0
A42: Lotus | B42: =2388+2166+2181+2143+2735+2159+2232+3124+2401+2891+2264+3229 -> 29913 | C42: 4554 | D42: =1591+185 -> 1776 | E42: =F42+G42+H42+I42+J42 -> 185 | F42: 61 | G42: 124 | K42: 185 | L42: =61+4 -> 65 | N42: 42 | O42: =+D42/C42 -> 0.38998682
A43: Phuoc Long ICD | B43: 12038 | C43: 1961 | D43: =1121+1436 -> 2557 | E43: =F43+G43+H43+I43+J43 -> 1436 | F43: 270 | G43: 1166 | K43: =19+368 -> 387 | L43: =21 -> 21 | N43: 1436 | O43: =+D43/C43 -> 1.3039266
A45: BR-VT | B45: =SUM(B46:B53) -> 4797590 | C45: =SUM(C46:C53) -> 567207 | D45: =SUM(D46:D53) -> 865603 | E45: =SUM(E46:E53) -> 396091 | F45: =SUM(F46:F53) -> 170682 | G45: =SUM(G46:G53) -> 186939 | H45: =SUM(H46:H53) -> 6230 | I45: =SUM(I46:I53) -> 3558 | ... N45: =SUM(N46:N53) -> 45250 | O45: =+D45/C45 -> 1.5260795
...

Sheet T03-2024
A1: VPA - SẢN LƯỢNG CONTAINER (TEU) - THÁNG 3 NĂM 2024 / 2023
A3: KHU VỰC / Cảng | B3: Năm 2023 | C3: 3T 2023 | D3: 3T 2024 | E3: THÁNG 3-2024 | O3: 3T (2024 / 2023)
E4: CỘNG | F4: Nhập Ngoại | G4: Xuất Ngoại | H4: Nhập nội | I4: Xuất nội | J4: Trung chuyển | K4: 20' | L4: Rỗng | M4: Lạnh | N4: GN qua sà lan
A6: MIỀN BẮC | B6: =SUM(B8:B18) -> 4518182 | C6: =SUM(C8:C17) -> 937239 | D6: =SUM(D8:D18) -> 1213842 | E6: =SUM(E8:E18) -> 440777 | F6: =SUM(F8:F17) -> 181324 | G6: =SUM(G8:G17) -> 174400 | H6: =SUM(H8:H17) -> 33903 | I6: =SUM(I8:I17) -> 33816 | O6: =+D6/C6 -> 1.2951254
A7: Quang Ninh | E7: =SUM(F7:J7) -> 0
A8: Cái Lân (CICT) | E8: =SUM(F8:J8) -> 0
A9: Hai Phong (Chùa Vẽ+Tân Vũ) | B9: =715133+126685+111732+106510+95851+111311 -> 1267222 | C9: =82758+91092+118158 -> 292008 | D9: =108077+85467+113186 -> 306730 | E9: =SUM(F9:J9) -> 113186 | F9: 41601 | G9: 38371 | H9: 18288 | I9: 14926 | O9: =+D9/C9 -> 1.0504164
A10: HICT (Lạch Huyện, HP) | B10: 1272859 | C10: =86070+54004+87940 -> 228014 | D10: =148719+103732+138638 -> 391089 | E10: =SUM(F10:J10) -> 138638 | F10: 68827 | G10: 69811 | K10: =8023+8816 -> 16839 | L10: =2206+547 -> 2753 | O10: =+D10/C10 -> 1.7151973
A11: Đoạn Xá | E11: =SUM(F11:J11) -> 0
A12: Đình vũ | B12: 491959 | C12: =73578+42605 -> 116183 | D12: =39231+38035+45839 -> 123105 | E12: =SUM(F12:J12) -> 45839 | F12: 22862 | G12: 21645 | H12: 496 | I12: 836 | O12: =+D12/C12 -> 1.0595784
A13: Nam Hải Đình Vũ | B13: 149160 | C13: =65905+27400 -> 93305 | D13: 0 | E13: =SUM(F13:J13) -> 0
A14: Nam Đình Vũ | B14: =27700+42263+60649+60306+68982+89333+103549+96251+80177+83538+83985+100491 -> 897224 | C14: =27700+42263+60649 -> 130612 | D14: =107401+71667+97692 -> 276760 | E14: =SUM(F14:J14) -> 97692 | F14: 45662 | G14: 42066 | H14: 4367 | I14: 5597 | K14: 24730 | L14: =3439+6882+423+396 -> 11140 | M14: 6769 | N14: 1095 | O14: =+D14/C14 -> 2.1189477
A15: Tân Cảng 128 Hải Phòng | B15: =6147+7479+7850+9613+8350+10297+8331+8950+9929+9191+7491+7125 -> 100753 | C15: =6147+7479+7850 -> 21476 | D15: =5818+3471+4879 -> 14168 | E15: =SUM(F15:J15) -> 4879 | F15: 2372 | G15: 2507 | K15: =650+526 -> 1176 | L15: =54+341 -> 395 | O15: =+D15/C15 -> 0.65971317
A16: Transvina | B16: =540+350 -> 890 | C16: =436+48 -> 484 | D16: 48 | E16: 48
A17: PTSC Đình Vũ | B17: =14801+21013+19343+20052+25339+15490+23521+25450+24091+25115+25902+30182 -> 270299 | C17: =14801+21013+19343 -> 55157 | D17: =29509+14652+23209 -> 67370 | E17: =SUM(F17:J17) -> 23209 | H17: 10752 | I17: 12457 | K17: 6747 | L17: =26+1331 -> 1357 | O17: =+D17/C17 -> 1.2214225
A18: VIMC Đình Vũ | B18: 67816 | D18: 34572 | E18: 17286
A19: Vip Green Port (*) | B19: 633659 | C19: 153559 | D19: 161928 | E19: 41734 | O19: =+D19/C19 -> 1.0545002
A20: Green Port (*) | B20: 255481 | C20: 62895 | D20: 65139 | E20: 17640 | O20: =+D20/C20 -> 1.0356785
A21: Mipec (*) | B21: 92242 | C21: 36650 | D21: 15392 | E21: 4335 | O21: =+D21/C21 -> 0.41997271
A22: Hải An (*) | B22: 400078 | C22: 87163 | D22: 105619 | E22: 30507 | O22: =+D22/C22 -> 1.2117412
A23: TC 189 Hải Phòng (*) | B23: 171077 | C23: 42937 | D23: 49437 | E23: 12059 | O23: =+D23/C23 -> 1.1513846
A24: Nam Hải Dình Vũ (*) | B24: 270677 | C24: 93350 | D24: 44825 | E24: 9654 | O24: =+D24/C24 -> 0.48018211
A26: MIỀN TRUNG | B26: =SUM(B27:B30) -> 860026 | C26: =SUM(C27:C30) -> 199040 | D26: =SUM(D27:D30) -> 237956 | E26: =SUM(E27:E30) -> 84611 | F26: =SUM(F27:F30) -> 28311 | G26: =SUM(G27:G30) -> 33680 | H26: =SUM(H27:H30) -> 12919 | I26: =SUM(I27:I30) -> 9701 | ... L26: =SUM(L27:L30) -> 3846 | N26: =SUM(N27:N30) -> 0 | O26: =+D26/C26 -> 1.1955185
A27: Nghe Tinh | B27: =30481+3346 -> 33827 | C27: =5142+2738 -> 7880 | D27: =4188+2189+2953 -> 9330 | E27: =SUM(F27:J27) -> 2953 | H27: 1280 | I27: 1673 | K27: 1629 | L27: =304 -> 304 | O27: =+D27/C27 -> 1.1840102
A28: Da Nang | B28: 675254 | C28: =42268+44857+61528 -> 148653 | D28: =64505+48073+62185 -> 174763 | E28: =SUM(F28:J28) -> 62185 | F28: 22176 | G28: 24180 | H28: 8051 | I28: 7778 | K28: =4578+5146+1858+803 -> 12385 | L28: =592+336+559+1043 -> 2530 | O28: =+D28/C28 -> 1.1756439
A29: Quy Nhon | B29: =120488+12239+18218 -> 150945 | C29: =15404+10234+16869 -> 42507 | D29: =22490+11900+19473 -> 53863 | E29: =SUM(F29:J29) -> 19473 | F29: 6135 | G29: 9500 | H29: 3588 | I29: 250 | K29: =329+1129+143+124 -> 1725 | L29: =592+35+337+48 -> 1012 | O29: =+D29/C29 -> 1.267156
A30: Cam Ranh | B30: 0 | C30: 0 | E30: =F30+G30+H30+I30+J30 -> 0
A32: TP HCM | B32: =SUM(B33:B43) -> 8314054 | C32: =SUM(C33:C43) -> 1873241 | D32: =SUM(D33:D43) -> 2114046 | E32: =SUM(E33:E43) -> 763512 | F32: =SUM(F33:F43) -> 295535 | G32: =SUM(G33:G43) -> 256030 | H32: =SUM(H33:H43) -> 93428 | I32: =SUM(I33:I43) -> 117574 | ... N32: =SUM(N33:N43) -> 67978 | O32: =+D32/C32 -> 1.1285499
A33: Binh Duong | B33: =439746+58130+61049 -> 558925 | C33: =39360+31413+40944 -> 111717 | D33: 176793 | E33: =SUM(F33:J33) -> 57750 | H33: 18731 | I33: 39019 | K33: 1718 | L33: =14572 -> 14572 | O33: =+D33/C33 -> 1.5825076
A34: Đồng Nai | B34: =506252+63971 -> 570223 | C34: =32272+30238+40100 -> 102610 | D34: =58796+40986+58237 -> 158019 | E34: =SUM(F34:J34) -> 58237 | H34: 9334 | I34: 48903 | K34: 2429 | L34: =9141+8 -> 9149 | N34: 58237 | O34: =+D34/C34 -> 1.5399961
A35: ITC- CORP | B35: =42017+51282+45948+47390+55304+49234+45680+47437+43911+34616+30188+41910 -> 534917 | C35: =42017+51282+45948 -> 139247 | D35: =43919+38655+49389 -> 131963 | E35: =SUM(F35:J35) -> 49389 | F35: 17718 | G35: 24942 | H35: 2520 | I35: 3337 | J35: 872 | K35: =7963+18741+1494+1328+268 -> 29794 | L35: =1195+154+105+121+220 -> 1795 | N35: 8443 | O35: =+D35/C35 -> 0.94769008 | P35: Dieu chinh
A36: Cảng Sai Gòn | B36: =154869+18461+17185+18184+22072 -> 230771 | C36: =9329+13814+20636 -> 43779 | D36: =20214+11681+23581 -> 55476 | E36: =SUM(F36:J36) -> 23581 | G36: 49 | H36: 11426 | I36: 12106 | K36: =49+2931+3501 -> 6481 | L36: =1009+605 -> 1614 | M36: 224 | O36: =+D36/C36 -> 1.2671829
A37: Ben Nghe | B37: =50925+32855+32535+28886+28236+30552+33558+32390+29858+33841+31383 -> 365019 | C37: =50925+32855 -> 83780 | D37: =36191+20920+29070 -> 86181 | E37: =SUM(F37:J37) -> 29070 | H37: 14861 | I37: 14209 | K37: =4498+4628 -> 9126 | L37: =361+3 -> 364 | N37: 40 | O37: =+D37/C37 -> 1.0286584
A38: Tan Cang - Hiệp Phước | B38: =5696+3958+5815+9110+7468+13154+12856+16704+16494+13524+11707+13991 -> 130477 | C38: =5696+3958+5815 -> 15469 | D38: =12008+9467+14763 -> 36238 | E38: =SUM(F38:J38) -> 14763 | F38: 4485 | G38: 10205 | J38: 73 | K38: =1737+1888 -> 3625 | L38: =60+1231+47 -> 1338 | N38: 36 | O38: =+D38/C38 -> 2.3426207
A39: Tan Cang - Cat Lai | B39: =372397+393542+480876+438506+433683+444706+469051+460647+432596+460939+470477+474708 -> 5332128 | C39: =372397+393542+480876 -> 1246815 | D39: =492323+373517+489518 -> 1355358 | E39: =SUM(F39:J39) -> 489518 | F39: 269644 | G39: 219874 | K39: 164862 | L39: =34561+16350 -> 50911 | O39: =+D39/C39 -> 1.0870562
A40: VICT | B40: =32440+39588+48102+43548+41412+40968+51704+51435+55440+57617+45700+41689 -> 549643 | C40: =32440+39588+48102 -> 120130 | D40: =41444+27037+39698 -> 108179 | E40: =SUM(F40:J40) -> 39698 | F40: 3142 | H40: 36556 | O40: =+D40/C40 -> 0.90051611
A41: SPCT | B41: =SUM(D41:G41) -> 0 | C41: =SUM(D41:G41) -> 0 | E41: =SUM(F41:J41) -> 0
A42: Lotus | B42: =2388+2166+2181+2143+2735+2159+2232+3124+2401+2891+2264+3229 -> 29913 | C42: =2388+2166+2181 -> 6735 | D42: =1591+185+300 -> 2076 | E42: =SUM(F42:J42) -> 300 | F42: 148 | G42: 152 | K42: 300 | L42: =148 -> 148 | N42: 16 | O42: =+D42/C42 -> 0.30824053
A43: Phuoc Long ICD | B43: 12038 | C43: =856+1105+998 -> 2959 | D43: =1121+1436+1206 -> 3763 | E43: =SUM(F43:J43) -> 1206 | F43: 398 | G43: 808 | K43: =37+186 -> 223 | L43: =29 -> 29 | N43: 1206 | O43: =+D43/C43 -> 1.2717134
A45: BR-VT | B45: =SUM(B46:B53) -> 4797590 | C45: =SUM(C46:C53) -> 969140 | D45: =SUM(D46:D53) -> 1320548 | E45: =SUM(E46:E53) -> 454945 | F45: =SUM(F46:F53) -> 193996 | G45: =SUM(G46:G53) -> 231086 | H45: =SUM(H46:H53) -> 5745 | I45: =SUM(I46:I53) -> 2677 | ... N45: =SUM(N46:N53) -> 40409 | O45: =+D45/C45 -> 1.3625978
...

Sheet T04-2024
A1: VPA - SẢN LƯỢNG CONTAINER (TEU) - THÁNG 4 NĂM 2024 / 2023
A3: KHU VỰC / Cảng | B3: Năm 2023 | C3: 4T 2023 | D3: 4T 2024 | E3: THÁNG 4-2024 | O3: 4T (2024 / 2023)
E4: CỘNG | F4: Nhập Ngoại | G4: Xuất Ngoại | H4: Nhập nội | I4: Xuất nội | J4: Trung chuyển | K4: 20' | L4: Rỗng | M4: Lạnh | N4: GN qua sà lan
A6: MIỀN BẮC | B6: =SUM(B8:B18) -> 4518182 | C6: =SUM(C8:C18) -> 1300764 | D6: =SUM(D8:D18) -> 1651414 | E6: =SUM(E8:E18) -> 433766 | F6: =SUM(F8:F17) -> 179216 | G6: =SUM(G8:G17) -> 178752 | H6: =SUM(H8:H17) -> 29623 | I6: =SUM(I8:I17) -> 34760 | O6: =+D6/C6 -> 1.2695723
A7: Quang Ninh | E7: =SUM(F7:J7) -> 0
A8: Cái Lân (CICT) | E8: =SUM(F8:J8) -> 0
A9: Hai Phong (Chùa Vẽ+Tân Vũ) | B9: =715133+126685+111732+106510+95851+111311 -> 1267222 | C9: 393464 | D9: =108077+85467+113186+113042 -> 419772 | E9: =SUM(F9:J9) -> 113042 | F9: 42090 | G9: 42696 | H9: 11676 | I9: 16580 | O9: =+D9/C9 -> 1.0668625
A10: HICT (Lạch Huyện, HP) | B10: 1272859 | C10: 325328 | D10: =148719+103732+138638+114388 -> 505477 | E10: =SUM(F10:J10) -> 114388 | F10: 52399 | G10: 61989 | K10: =7464+7196 -> 14660 | L10: =2121+779 -> 2900 | O10: =+D10/C10 -> 1.5537458
A11: Đoạn Xá | E11: =SUM(F11:J11) -> 0
A12: Đình vũ | B12: 491959 | C12: 158796 | D12: =39231+38035+45839+55212 -> 178317 | E12: =SUM(F12:J12) -> 55212 | F12: 28482 | G12: 24879 | H12: 1284 | I12: 567 | K12: =7787+3629+242+85 -> 11743 | L12: =29+3020+242+6 -> 3297 | M12: 0 | N12: 0 | O12: =+D12/C12 -> 1.1229313
A13: Nam Hải Đình Vũ | B13: 149160 | C13: 122737 | D13: 0 | E13: =SUM(F13:J13) -> 0
A14: Nam Đình Vũ | B14: =27700+42263+60649+60306+68982+89333+103549+96251+80177+83538+83985+100491 -> 897224 | C14: 190918 | D14: =107401+71667+97692+112321 -> 389081 | E14: =SUM(F14:J14) -> 112321 | F14: 56245 | G14: 49188 | H14: 3248 | I14: 3640 | K14: =12240+9149+672+962 -> 23023 | L14: =1231+4145+70+46 -> 5492 | M14: 4808 | N14: 452 | O14: =+D14/C14 -> 2.0379482
A15: Tân Cảng 128 Hải Phòng | B15: =6147+7479+7850+9613+8350+10297+8331+8950+9929+9191+7491+7125 -> 100753 | C15: 31089 | D15: =5818+3471+4879+3146 -> 17314 | E15: =SUM(F15:J15) -> 3146 | H15: 1502 | I15: 1644 | K15: 678 | L15: =283+670 -> 953 | N15: 3146 | O15: =+D15/C15 -> 0.55691724
A16: Transvina | B16: =540+350 -> 890 | C16: 0 | D16: =528 -> 528 | E16: 44
A17: PTSC Đình Vũ | B17: =14801+21013+19343+20052+25339+15490+23521+25450+24091+25115+25902+30182 -> 270299 | C17: 75209 | D17: =29509+14652+23209+24242 -> 91612 | E17: =SUM(F17:J17) -> 24242 | H17: 11913 | I17: 12329 | K17: 7162 | L17: =214+1539 -> 1753 | O17: =+D17/C17 -> 1.2180989
A18: VIMC Đình Vũ | B18: 67816 | C18: 3223 | D18: =37942+11371 -> 49313 | E18: 11371
A19: Vip Green Port (*) | B19: 633659 | C19: 153559 | D19: =161928+54011 -> 215939 | E19: 54011 | O19: =+D19/C19 -> 1.4062282
A20: Green Port (*) | B20: 255481 | C20: 62895 | D20: 86240 | E20: 21101 | O20: =+D20/C20 -> 1.3711742
A21: Mipec (*) | B21: 92242 | C21: 36650 | D21: =15392+5518 -> 20910 | E21: 5518 | O21: =+D21/C21 -> 0.57053206
A22: Hải An (*) | B22: 400078 | C22: 87163 | D22: =36183+30507+38929+42926 -> 148545 | E22: 42926 | O22: =+D22/C22 -> 1.7042208
A23: TC 189 Hải Phòng (*) | B23: 171077 | C23: 42937 | D23: 60794 | E23: 11357 | O23: =+D23/C23 -> 1.4158884
A24: Nam Hải Dình Vũ (*) | B24: 270677 | C24: 93350 | D24: =22071+9654+13100+21751 -> 66576 | E24: 21751 | O24: =+D24/C24 -> 0.71318693
A25: Nam Hải | D25: =3457+12735 -> 16192 | E25: 16192
A28: MIỀN TRUNG | B28: =SUM(B29:B32) -> 860026 | C28: =SUM(C29:C32) -> 267214 | D28: =SUM(D29:D32) -> 320362 | E28: =SUM(E29:E32) -> 82406 | F28: =SUM(F29:F32) -> 28771 | G28: =SUM(G29:G32) -> 33832 | H28: =SUM(H29:H32) -> 11638 | I28: =SUM(I29:I32) -> 8165 | ... L28: =SUM(L29:L32) -> 4788 | N28: =SUM(N29:N32) -> 0 | O28: =+D28/C28 -> 1.1988968
A29: Nghe Tinh | B29: =30481+3346 -> 33827 | C29: 10163 | D29: =4188+2189+2953+3363 -> 12693 | E29: =SUM(F29:J29) -> 3363 | H29: 1788 | I29: 1575 | K29: 1471 | L29: =1027+1 -> 1028 | O29: =+D29/C29 -> 1.2489422
A30: Da Nang | B30: 675254 | C30: 202656 | D30: =64505+48073+62185+62452 -> 237215 | E30: =SUM(F30:J30) -> 62452 | F30: 22899 | G30: 25053 | H30: 7988 | I30: 6512 | K30: =4375+3715+1553+1004 -> 10647 | L30: =384+1560+389+788 -> 3121 | O30: =+D30/C30 -> 1.1705304
A31: Quy Nhon | B31: =120488+12239+18218 -> 150945 | C31: 54395 | D31: =22490+11900+19473+16591 -> 70454 | E31: =SUM(F31:J31) -> 16591 | F31: 5872 | G31: 8779 | H31: 1862 | I31: 78 | K31: =177+991+79+69 -> 1316 | L31: =437+8+189+5 -> 639 | M31: 0 | N31: 0 | O31: =+D31/C31 -> 1.2952293
A32: Cam Ranh | B32: 0 | E32: =F32+G32+H32+I32+J32 -> 0
A34: TP HCM | B34: =SUM(B35:B45) -> 8314054 | C34: =SUM(C35:C45) -> 2559334 | D34: =SUM(D35:D45) -> 2898765 | E34: =SUM(E35:E45) -> 784719 | F34: =SUM(F35:F45) -> 338620 | G34: =SUM(G35:G45) -> 295109 | H34: =SUM(H35:H45) -> 74547 | I34: =SUM(I35:I45) -> 75579 | ... N34: =SUM(N35:N45) -> 62104 | O34: =+D34/C34 -> 1.1326247
A35: Binh Duong | B35: =439746+58130+61049 -> 558925 | C35: 160002 | D35: =176793+71526 -> 248319 | E35: =SUM(F35:J35) -> 71526 | F35: 19960 | G35: 51566 | O35: =+D35/C35 -> 1.5519744
A36: Đồng Nai | B36: =506252+63971 -> 570223 | C36: 151336 | D36: =58796+40986+58237+58418 -> 216437 | E36: =SUM(F36:J36) -> 58418 | H36: 10441 | I36: 47977 | K36: =68+1725 -> 1793 | L36: =257+0 -> 257 | M36: 128 | N36: 58418 | O36: =+D36/C36 -> 1.4301752
A37: ITC- CORP | B37: =42017+51282+45948+47390+55304+49234+45680+47437+43911+34616+30188+41910 -> 534917 | C37: 186637 | D37: =43919+38655+49389+49920 -> 181883 | E37: =SUM(F37:J37) -> 49920 | F37: 20373 | G37: 23783 | H37: 2526 | I37: 2422 | J37: 816 | K37: =1224+7305+622+401+54 -> 9606 | L37: =1224+138+46+1+198 -> 1607 | N37: 1876 | O37: =+D37/C37 -> 0.97452809
A38: Cảng Sai Gòn | B38: =154869+18461+17185+18184+22072 -> 230771 | C38: 58532 | D38: =20214+11681+23581+25619 -> 81095 | E38: =SUM(F38:J38) -> 25619 | H38: 13073 | I38: 12546 | K38: =3260+2945 -> 6205 | L38: =735+719 -> 1454 | M38: 197 | N38: 0 | O38: =+D38/C38 -> 1.3854814
A39: Ben Nghe | B39: =50925+32855+32535+28886+28236+30552+33558+32390+29858+33841+31383 -> 365019 | C39: 116315 | D39: =36191+20920+29070+23929 -> 110110 | E39: =SUM(F39:J39) -> 23929 | H39: 12388 | I39: 11541 | K39: =4187+3694 -> 7881 | L39: =169+217 -> 386 | O39: =+D39/C39 -> 0.94665348
A40: Tan Cang - Hiệp Phước | B40: =5696+3958+5815+9110+7468+13154+12856+16704+16494+13524+11707+13991 -> 130477 | C40: 24579 | D40: =12008+9467+14763+14113 -> 50351 | E40: =SUM(F40:J40) -> 14113 | F40: 4135 | G40: 7885 | H40: 952 | I40: 1093 | J40: 48 | K40: 5853 | L40: =920+4510+384+534+48 -> 6396 | N40: 11 | O40: =+D40/C40 -> 2.0485374
A41: Tan Cang - Cat Lai | B41: =372397+393542+480876+438506+433683+444706+469051+460647+432596+460939+470477+474708 -> 5332128 | C41: 1685321 | D41: =492323+373517+489518+501319 -> 1856677 | E41: =SUM(F41:J41) -> 501319 | F41: 290627 | G41: 210692 | K41: 166691 | L41: =38093+19602 -> 57695 | O41: =+D41/C41 -> 1.1016756
A42: VICT | B42: =32440+39588+48102+43548+41412+40968+51704+51435+55440+57617+45700+41689 -> 549643 | C42: 163678 | D42: =41444+27037+39698+37856 -> 146035 | E42: =SUM(F42:J42) -> 37856 | F42: 2689 | H42: 35167 | O42: =+D42/C42 -> 0.89220909
A43: SPCT | B43: =SUM(D43:G43) -> 0 | C43: 0 | E43: =SUM(F43:J43) -> 0
A44: Lotus | B44: =2388+2166+2181+2143+2735+2159+2232+3124+2401+2891+2264+3229 -> 29913 | C44: 8878 | D44: =1591+185+300+228 -> 2304 | E44: =SUM(F44:J44) -> 228 | F44: 131 | G44: 97 | K44: 228 | L44: =131 -> 131 | N44: 8 | O44: =+D44/C44 -> 0.25951791
A45: Phuoc Long ICD | B45: 12038 | C45: 4056 | D45: 5554 | E45: =SUM(F45:J45) -> 1791 | F45: 705 | G45: 1086 | K45: =62+234 -> 296 | L45: 189 | N45: 1791 | O45: =+D45/C45 -> 1.3693294
...

Sheet T05-2024
A1: VPA - SẢN LƯỢNG CONTAINER (TEU) - THÁNG 5 NĂM 2024 / 2023
A3: KHU VỰC / Cảng | B3: Năm 2023 | C3: 5T 2023 | D3: 5T 2024 | E3: THÁNG 5-2024 | O3: 5T (2024 / 2023)
E4: CỘNG | F4: Nhập Ngoại | G4: Xuất Ngoại | H4: Nhập nội | I4: Xuất nội | J4: Trung chuyển | K4: 20' | L4: Rỗng | M4: Lạnh | N4: GN qua sà lan
A6: MIỀN BẮC | B6: =SUM(B8:B18) -> 4518182 | C6: 1679704 | D6: =SUM(D8:D18) -> 2112505 | E6: =SUM(E8:E18) -> 461091 | F6: =SUM(F8:F17) -> 203309 | G6: =SUM(G8:G17) -> 189387 | H6: =SUM(H8:H17) -> 24793 | I6: =SUM(I8:I17) -> 29711 | O6: =+D6/C6 -> 1.257665
A7: Quang Ninh | E7: =SUM(F7:J7) -> 0
A8: Cái Lân (CICT) | E8: =SUM(F8:J8) -> 0
A9: Hai Phong (Chùa Vẽ+Tân Vũ) | B9: =715133+126685+111732+106510+95851+111311 -> 1267222 | C9: 497600 | D9: =108077+85467+113186+113042+116756 -> 536528 | E9: =SUM(F9:J9) -> 116756 | F9: 44278 | G9: 43655 | H9: 13958 | I9: 14865 | O9: =+D9/C9 -> 1.0782315
A10: HICT (Lạch Huyện, HP) | B10: 1272859 | C10: 428772 | D10: =148719+103732+138638+114388+149772 -> 655249 | E10: =SUM(F10:J10) -> 149772 | F10: 78585 | G10: =71187 -> 71187 | K10: =8950+7298 -> 16248 | L10: =3649+1555 -> 5204 | O10: =+D10/C10 -> 1.5281991
A11: Đoạn Xá | E11: =SUM(F11:J11) -> 0
A12: Đình vũ | B12: 491959 | C12: 197010 | D12: =39231+38035+45839+55212+55252 -> 233569 | E12: =SUM(F12:J12) -> 55252 | F12: 28755 | G12: 25693 | H12: 239 | I12: 565 | J12: 0 | N12: 0 | O12: =+D12/C12 -> 1.1855693
A13: Nam Hải Đình Vũ | B13: 149160 | C13: 149160 | D13: 0 | E13: =SUM(F13:J13) -> 0
A14: Nam Đình Vũ | B14: =27700+42263+60649+60306+68982+89333+103549+96251+80177+83538+83985+100491 -> 897224 | C14: 259900 | D14: =107401+71667+97692+112321+100543 -> 489624 | E14: =SUM(F14:J14) -> 100543 | F14: 51691 | G14: 48852 | K14: =12088+7515 -> 19603 | L14: =905+5185 -> 6090 | M14: 6174 | N14: 415 | O14: =+D14/C14 -> 1.8838938
A15: Tân Cảng 128 Hải Phòng | B15: =6147+7479+7850+9613+8350+10297+8331+8950+9929+9191+7491+7125 -> 100753 | C15: 39439 | D15: =5818+3471+4879+3146+1868 -> 19182 | E15: =SUM(F15:J15) -> 1868 | H15: 933 | I15: 935 | K15: =172+213 -> 385 | L15: =53+18 -> 71 | N15: 0 | O15: =+D15/C15 -> 0.48637136
A16: Transvina | B16: =540+350 -> 890 | C16: 436 | D16: =528 -> 528 | E16: 0
A17: PTSC Đình Vũ | B17: =14801+21013+19343+20052+25339+15490+23521+25450+24091+25115+25902+30182 -> 270299 | C17: 100548 | D17: =29509+14652+23209+24242+23009 -> 114621 | E17: =SUM(F17:J17) -> 23009 | H17: 9663 | I17: 13346 | K17: =2763+3500 -> 6263 | L17: =32+188 -> 220 | O17: =+D17/C17 -> 1.139963
A18: VIMC Đình Vũ | B18: 67816 | C18: 7275 | D18: =37942+11371+13891 -> 63204 | E18: 13891 | O18: =+D18/C18 -> 8.6878351
A19: Vip Green Port (*) | B19: 633659 | C19: 262872 | D19: =161928+54011+52836 -> 268775 | E19: 52836 | O19: =+D19/C19 -> 1.0224558
A20: Green Port (*) | B20: 255481 | C20: 109228 | D20: =86240+22448 -> 108688 | E20: 22448 | O20: =+D20/C20 -> 0.99505621
A21: Mipec (*) | B21: 92242 | C21: 60593 | D21: =15392+5518+8672 -> 29582 | E21: 8672 | O21: =+D21/C21 -> 0.48820821
A22: Hải An (*) | B22: 400078 | C22: 403715 | D22: =36183+30507+38929+42926+38815 -> 187360 | E22: 38815 | O22: =+D22/C22 -> 0.46408977
A23: TC 189 Hải Phòng (*) | B23: 171077 | C23: 148142 | D23: =60794+15126 -> 75920 | E23: 15126 | O23: =+D23/C23 -> 0.51248127
A24: Nam Hải Dình Vũ (*) | B24: 270677 | D24: =22071+9654+13100+21751+25961 -> 92537 | E24: 25961
A25: Nam Hải | D25: =3457+12735+18119 -> 34311 | E25: 18119
A28: MIỀN TRUNG | B28: =SUM(B29:B32) -> 860026 | C28: 339710 | D28: =SUM(D29:D32) -> 395954 | E28: =SUM(E29:E32) -> 76068 | F28: =SUM(F29:F32) -> 27566 | G28: =SUM(G29:G32) -> 28847 | H28: =SUM(H29:H32) -> 11366 | I28: =SUM(I29:I32) -> 8289 | J28: =SUM(J29:J32) -> 0 | K28: =SUM(K29:K32) -> 12338 | L28: =SUM(L29:L32) -> 1580 | N28: =SUM(N29:N32) -> 0 | O28: =+D28/C28 -> 1.1655647
A29: Nghe Tinh | B29: =30481+3346 -> 33827 | C29: 13573 | D29: 15606 | E29: 3389 | H29: 1689 | I29: 1700 | K29: =473+678 -> 1151 | L29: =147+7 -> 154 | O29: =+D29/C29 -> 1.1497827
A30: Da Nang | B30: 675254 | C30: 259916 | D30: =64505+48073+62185+62452+59765 -> 296980 | E30: =SUM(F30:J30) -> 59765 | F30: 22888 | G30: 23059 | H30: 7411 | I30: 6407 | K30: =4095+3452+1413+991 -> 9951 | L30: =63+761+308 -> 1132 | M30: 0 | N30: 0 | O30: =+D30/C30 -> 1.1425999
A31: Quy Nhon | B31: =120488+12239+18218 -> 150945 | C31: 67221 | D31: =22490+11900+19473+16591+12914 -> 83368 | E31: =SUM(F31:J31) -> 12914 | F31: 4678 | G31: 5788 | H31: 2266 | I31: 182 | K31: =338+623+141+134 -> 1236 | L31: =194+3+97 -> 294 | O31: =+D31/C31 -> 1.2402077
A32: Cam Ranh | B32: 0 | C32: 0 | E32: =F32+G32+H32+I32+J32 -> 0
A34: TP HCM | B34: =SUM(B35:B45) -> 8314054 | C34: 3239967 | D34: =SUM(D35:D45) -> 3657494 | E34: =SUM(E35:E45) -> 758729 | F34: =SUM(F35:F45) -> 311266 | G34: =SUM(G35:G45) -> 239478 | H34: =SUM(H35:H45) -> 97378 | I34: =SUM(I35:I45) -> 109192 | J34: =SUM(J35:J45) -> 1415 | K34: =SUM(K35:K45) -> 169421 | ... N34: =SUM(N35:N45) -> 57713 | O34: =+D34/C34 -> 1.1288677
A35: Binh Duong | B35: =439746+58130+61049 -> 558925 | C35: 203006 | D35: =176793+71526+59980 -> 308299 | E35: =SUM(F35:J35) -> 59980 | H35: 19701 | I35: 40279 | K35: =24+1405 -> 1429 | L35: =375 -> 375 | O35: =+D35/C35 -> 1.5186694
A36: Đồng Nai | B36: =506252+63971 -> 570223 | C36: 198808 | D36: =58796+40986+58237+58418+48813 -> 265250 | E36: =SUM(F36:J36) -> 48813 | H36: 8824 | I36: 39989 | K36: =63+1237 -> 1300 | L36: =655 -> 655 | N36: 48813 | O36: =+D36/C36 -> 1.3342018
A37: ITC- CORP | B37: =42017+51282+45948+47390+55304+49234+45680+47437+43911+34616+30188+41910 -> 534917 | C37: 241941 | D37: =43919+38655+49389+49920+41452 -> 223335 | E37: =SUM(F37:J37) -> 41452 | F37: 15922 | G37: 18129 | H37: 2999 | I37: 3028 | J37: 1374 | K37: =3247+5392+825+459+40 -> 9963 | L37: =637+75+77+490 -> 1279 | M37: 3068 | O37: =+D37/C37 -> 0.92309695
A38: Cảng Sai Gòn | B38: =154869+18461+17185+18184+22072 -> 230771 | C38: 78439 | D38: =20214+11681+23581+25619+22301 -> 103396 | E38: =SUM(F38:J38) -> 22301 | G38: 8 | H38: 11231 | I38: 11062 | K38: =3250+2469 -> 5719 | L38: =409+941 -> 1350 | M38: 443 | N38: 0 | O38: =+D38/C38 -> 1.3181708
A39: Ben Nghe | B39: =50925+32855+32535+28886+28236+30552+33558+32390+29858+33841+31383 -> 365019 | C39: 145201 | D39: =36191+20920+29070+23929+27875 -> 137985 | E39: =SUM(F39:J39) -> 27875 | H39: 14240 | I39: 13635 | K39: =5016+4163 -> 9179 | L39: =248+980 -> 1228 | M39: 304 | N39: 603 | O39: =+D39/C39 -> 0.95030337 | P39: R
A40: Tan Cang - Hiệp Phước | B40: =5696+3958+5815+9110+7468+13154+12856+16704+16494+13524+11707+13991 -> 130477 | C40: 32047 | D40: =12008+9467+14763+14113+14691 -> 65042 | E40: =SUM(F40:J40) -> 14691 | F40: 3600 | G40: 8885 | H40: 966 | I40: 1199 | J40: 41 | K40: =1530+1619+303+118 -> 3570 | L40: =10+1838+13+343+21 -> 2225 | N40: 4 | O40: =+D40/C40 -> 2.0295816
A41: Tan Cang - Cat Lai | B41: =372397+393542+480876+438506+433683+444706+469051+460647+432596+460939+470477+474708 -> 5332128 | C41: 2119004 | D41: =492323+373517+489518+501319+498148 -> 2354825 | E41: =SUM(F41:J41) -> 498148 | F41: 287038 | G41: 211110 | K41: =78837+59050 -> 137887 | L41: =5635+13812 -> 19447 | O41: =+D41/C41 -> 1.1112886
A42: VICT | B42: =32440+39588+48102+43548+41412+40968+51704+51435+55440+57617+45700+41689 -> 549643 | C42: 205090 | D42: =41444+27037+39698+37856+42480 -> 188515 | E42: =SUM(F42:J42) -> 42480 | F42: 3063 | H42: 39417 | O42: =+D42/C42 -> 0.91918182
A43: SPCT | B43: =SUM(D43:G43) -> 0 | C43: 0 | E43: =SUM(F43:J43) -> 0
A44: Lotus | B44: =2388+2166+2181+2143+2735+2159+2232+3124+2401+2891+2264+3229 -> 29913 | C44: 11613 | D44: =1591+185+300+228+282 -> 2586 | E44: =SUM(F44:J44) -> 282 | F44: 97 | G44: 185 | K44: =185 -> 185 | L44: =97 -> 97 | N44: 32 | O44: =+D44/C44 -> 0.22268148
A45: Phuoc Long ICD | B45: 12038 | C45: 4818 | D45: =5554+2707 -> 8261 | E45: =SUM(F45:J45) -> 2707 | F45: 1546 | G45: 1161 | K45: =54+135 -> 189 | L45: =138+2 -> 140 | N45: 8261 | O45: =+D45/C45 -> 1.7146119
...

Sheet T06-2024
A1: VPA - SẢN LƯỢNG CONTAINER (TEU) - THÁNG 6 NĂM 2024 / 2023
A3: KHU VỰC / Cảng | B3: Năm 2023 | C3: 6T 2023 | D3: 6T 2024 | E3: THÁNG 6-2024 | O3: 6T (2024 / 2023)
E4: CỘNG | F4: Nhập Ngoại | G4: Xuất Ngoại | H4: Nhập nội | I4: Xuất nội | J4: Trung chuyển | K4: 20' | L4: Rỗng | M4: Lạnh | N4: GN qua sà lan
A6: MIỀN BẮC | B6: =SUM(B8:B18) -> 4518182 | C6: 2045930 | D6: =SUM(D8:D18) -> 2552943 | E6: =SUM(E8:E18) -> 440438 | F6: =SUM(F8:F18) -> 178820 | G6: =SUM(G8:G18) -> 189914 | H6: =SUM(H8:H18) -> 29055 | I6: =SUM(I8:I18) -> 29781 | J6: =SUM(J8:J18) -> 0 | K6: =SUM(K8:K18) -> 53822 | ... N6: =SUM(N8:N18) -> 872 | O6: =+D6/C6 -> 1.2478154
A7: Quang Ninh | E7: =SUM(F7:J7) -> 0
A8: Cái Lân (CICT) | E8: =SUM(F8:J8) -> 0
A9: Hai Phong (Chùa Vẽ+Tân Vũ) | B9: =715133+126685+111732+106510+95851+111311 -> 1267222 | C9: 605828 | D9: =108077+85467+113186+113042+116756+109995 -> 646523 | E9: =SUM(F9:J9) -> 109995 | F9: 42652 | G9: 39121 | H9: 13675 | I9: 14547 | O9: =+D9/C9 -> 1.0671725
A10: HICT (Lạch Huyện, HP) | B10: 1272859 | C10: 527720 | D10: =148719+103732+138638+114388+149772+144287 -> 799536 | E10: =SUM(F10:J10) -> 144287 | F10: 63237 | G10: 81050 | K10: 19805 | L10: =32222+7617 -> 39839 | O10: =+D10/C10 -> 1.5150762
A11: Đoạn Xá | E11: =SUM(F11:J11) -> 0
A12: Đình vũ | B12: 491959 | C12: 238449 | D12: =39231+38035+45839+55212+55252+51874 -> 285443 | E12: =SUM(F12:J12) -> 51874 | F12: 26101 | G12: 24891 | H12: 211 | I12: 671 | K12: =8403+3528+15+203 -> 12149 | L12: =90+4095 -> 4185 | O12: =+D12/C12 -> 1.197082
A13: Nam Hải Đình Vũ | B13: 149160 | C13: 149160 | D13: 0 | E13: =SUM(F13:J13) -> 0 | O13: =+D13/C13 -> 0
A14: Nam Đình Vũ | B14: =27700+42263+60649+60306+68982+89333+103549+96251+80177+83538+83985+100491 -> 897224 | C14: 349233 | D14: =107401+71667+97692+112321+100543+91682 -> 581306 | E14: =SUM(F14:J14) -> 91682 | F14: 46830 | G14: 44852 | K14: =6169+8179 -> 14348 | L14: =807+3239 -> 4046 | M14: 5244 | N14: 872 | O14: =+D14/C14 -> 1.664522
A15: Tân Cảng 128 Hải Phòng | B15: =6147+7479+7850+9613+8350+10297+8331+8950+9929+9191+7491+7125 -> 100753 | C15: 49736 | D15: =5818+3471+4879+3146+1868+3203 -> 22385 | E15: =SUM(F15:J15) -> 3203 | H15: 1608 | I15: 1595 | K15: =250+378 -> 628 | L15: =152+340 -> 492 | O15: =+D15/C15 -> 0.4500764
A16: Transvina | B16: =540+350 -> 890 | C16: 0 | D16: =528 -> 528 | E16: 0
A17: PTSC Đình Vũ | B17: =14801+21013+19343+20052+25339+15490+23521+25450+24091+25115+25902+30182 -> 270299 | C17: 116038 | D17: =29509+14652+23209+24242+23009+26529 -> 141150 | E17: =SUM(F17:J17) -> 26529 | H17: 13561 | I17: 12968 | K17: =3415+3477 -> 6892 | L17: =498+205 -> 703 | O17: =+D17/C17 -> 1.2164119
A18: VIMC Đình Vũ | B18: 67816 | C18: 9766 | D18: =63204+12868 -> 76072 | E18: 12868 | O18: =+D18/C18 -> 7.7894737
A19: Vip Green Port (*) | B19: 633659 | D19: =161928+54011+52836+59821 -> 328596 | E19: 59821
A20: Green Port (*) | B20: 255481 | D20: =86240+22448+23244 -> 131932 | E20: 23244
A21: Mipec (*) | B21: 92242 | D21: =15392+5518+8672+12966 -> 42548 | E21: 12966
A22: Hải An (*) | B22: 400078 | D22: =36183+30507+38929+42926+38815+41506 -> 228866 | E22: 41506
A23: TC 189 Hải Phòng (*) | B23: 171077 | D23: =60794+15126+16149 -> 92069 | E23: 16149
A24: Nam Hải Dình Vũ (*) | B24: 270677 | D24: =22071+9654+13100+21751+25961+15202 -> 107739 | E24: 15202
A25: Nam Hải | D25: =3457+12735+18119+18316 -> 52627 | E25: 18316
A28: MIỀN TRUNG | B28: =SUM(B29:B32) -> 860026 | C28: 408822 | D28: =SUM(D29:D32) -> 476708 | E28: =SUM(E29:E32) -> 80278 | F28: =SUM(F29:F32) -> 32079 | G28: =SUM(G29:G32) -> 29682 | H28: =SUM(H29:H32) -> 9733 | I28: =SUM(I29:I32) -> 8784 | J28: =SUM(J29:J32) -> 0 | K28: =SUM(K29:K32) -> 14762 | L28: =SUM(L29:L32) -> 2275 | N28: =SUM(N29:N32) -> 0 | O28: =+D28/C28 -> 1.1660527
A29: Nghe Tinh | B29: =30481+3346 -> 33827 | C29: 16221 | D29: =4188+2189+2953+3363+3389+2628 -> 18710 | E29: =SUM(F29:J29) -> 2628 | H29: 1278 | I29: 1350 | K29: =440+592 -> 1032 | L29: =72 -> 72 | O29: =+D29/C29 -> 1.1534431
A30: Da Nang | B30: 675254 | C30: 314655 | D30: =64505+48073+62185+62452+59765+64280 -> 361260 | E30: =SUM(F30:J30) -> 64280 | F30: 26597 | G30: 23520 | H30: 7133 | I30: 7030 | K30: =4790+4963+1582+1101 -> 12436 | L30: =429+573+415 -> 1417 | O30: =+D30/C30 -> 1.1481146
A31: Quy Nhon | B31: =120488+12239+18218 -> 150945 | C31: 77946 | D31: =22490+11900+19473+16591+12914+13370 -> 96738 | E31: =SUM(F31:J31) -> 13370 | F31: 5482 | G31: 6162 | H31: 1322 | I31: 404 | K31: =226+873+93+102 -> 1294 | L31: =564+3+215+4 -> 786 | O31: =+D31/C31 -> 1.24109
A32: Cam Ranh | B32: 0
A34: TP HCM | B34: =SUM(B35:B45) -> 8314054 | C34: 3943440 | D34: =SUM(D35:D45) -> 4409642 | E34: =SUM(E35:E45) -> 752148 | F34: =SUM(F35:F45) -> 295896 | G34: =SUM(G35:G45) -> 291533 | H34: =SUM(H35:H45) -> 89990 | I34: =SUM(I35:I45) -> 73393 | J34: =SUM(J35:J45) -> 1336 | K34: =SUM(K35:K45) -> 168668 | ... N34: =SUM(N35:N45) -> 54212 | O34: =+D34/C34 -> 1.1182222
A35: Binh Duong | B35: =439746+58130+61049 -> 558925 | C35: 252493 | D35: =176793+71526+59980+65204 -> 373503 | E35: =SUM(F35:J35) -> 65204 | G35: 47549 | H35: 17655 | K35: 2198 | L35: =13068 -> 13068 | O35: =+D35/C35 -> 1.4792608
A36: Đồng Nai -Điều chỉnh số liệu T6/2024 | B36: =506252+63971 -> 570223 | C36: 247412 | D36: =58796+40986+58237+58418+48813+50046 -> 315296 | E36: =H36+I36 -> 50046 | H36: 6906 | I36: 43140 | K36: 1540 | L36: =6783+10 -> 6793 | N36: 50046 | O36: =+D36/C36 -> 1.2743763
A37: ITC- CORP | B37: =42017+51282+45948+47390+55304+49234+45680+47437+43911+34616+30188+41910 -> 534917 | C37: 291175 | D37: =43919+38655+49389+49920+41452+46211 -> 269546 | E37: =SUM(F37:J37) -> 46211 | F37: 19037 | G37: 20258 | H37: 3009 | I37: 2571 | J37: 1336 | K37: =4120+5084+833+405+89 -> 10531 | L37: =859+196+40+316+659 -> 2070 | N37: 2407 | O37: =+D37/C37 -> 0.92571821
A38: Cảng Sai Gòn | B38: =154869+18461+17185+18184+22072 -> 230771 | C38: 104358 | D38: =20214+11681+23581+25619+22301+21824 -> 125220 | E38: =SUM(F38:J38) -> 21824 | G38: 20 | H38: 10791 | I38: 11013 | K38: =20+2969+2069 -> 5058 | L38: =296+1111 -> 1407 | M38: 236 | O38: =+D38/C38 -> 1.199908
A39: Ben Nghe | B39: =50925+32855+32535+28886+28236+30552+33558+32390+29858+33841+31383 -> 365019 | C39: 173437 | D39: =36191+20920+29070+23929+27875+30427 -> 168412 | E39: =SUM(F39:J39) -> 30427 | H39: 14961 | I39: 15466 | K39: 10453 | L39: =1830+2227 -> 4057 | M39: 298 | O39: =+D39/C39 -> 0.97102694
A40: Tan Cang - Hiệp Phước | B40: =5696+3958+5815+9110+7468+13154+12856+16704+16494+13524+11707+13991 -> 130477 | C40: 45201 | D40: =12008+9467+14763+14113+14691+14606 -> 79648 | E40: =SUM(F40:J40) -> 14606 | F40: 2830 | G40: 9053 | H40: 1520 | I40: 1203 | K40: =1080+1570+526+137 -> 3313 | L40: =1499+30+280 -> 1809 | O40: =+D40/C40 -> 1.7620849
A41: Tan Cang - Cat Lai | B41: =372397+393542+480876+438506+433683+444706+469051+460647+432596+460939+470477+474708 -> 5332128 | C41: 2563710 | D41: =492323+373517+489518+501319+498148+483300 -> 2838125 | E41: =SUM(F41:J41) -> 483300 | F41: 269687 | G41: 213613 | K41: =75140+60001 -> 135141 | L41: =3563+14142 -> 17705 | O41: =+D41/C41 -> 1.1070382
A42: VICT | B42: =32440+39588+48102+43548+41412+40968+51704+51435+55440+57617+45700+41689 -> 549643 | C42: 246058 | D42: =41444+27037+39698+37856+42480+38521 -> 227036 | E42: =SUM(F42:J42) -> 38521 | F42: 3373 | H42: 35148 | O42: =+D42/C42 -> 0.92269302
A43: SPCT | B43: =SUM(D43:G43) -> 0 | C43: 0
A44: Lotus | B44: =2388+2166+2181+2143+2735+2159+2232+3124+2401+2891+2264+3229 -> 29913 | C44: 13772 | D44: =1591+185+300+228+282+250 -> 2836 | E44: =SUM(F44:J44) -> 250 | F44: 124 | G44: 126 | K44: 250 | L44: =124 -> 124 | O44: =+D44/C44 -> 0.20592507
A45: Phuoc Long ICD | B45: 12038 | C45: 5824 | D45: =5554+2707+1759 -> 10020 | E45: =SUM(F45:F45:J45) -> 1759 | F45: 845 | G45: 914 | K45: =28+156 -> 184 | L45: =331 -> 331 | N45: 1759 | O45: =+D45/C45 -> 1.720467
...

Sheet T07-2024
A1: VPA - SẢN LƯỢNG CONTAINER (TEU) - THÁNG 7 NĂM 2024 / 2023
A3: KHU VỰC / Cảng | B3: Năm 2023 | C3: 7T 2023 | D3: 7T 2024 | E3: THÁNG 7-2024 | O3: 7T (2024 / 2023)
E4: CỘNG | F4: Nhập Ngoại | G4: Xuất Ngoại | H4: Nhập nội | I4: Xuất nội | J4: Trung chuyển | K4: 20' | L4: Rỗng | M4: Lạnh | N4: GN qua sà lan
A6: MIỀN BẮC | B6: =SUM(B8:B18) -> 4518182 | C6: 2435806 | D6: =SUM(D8:D18) -> 3013565 | E6: =SUM(E8:E18) -> 460622 | F6: =SUM(F8:F18) -> 196493 | G6: =SUM(G8:G18) -> 193818 | H6: =SUM(H8:H18) -> 29195 | I6: =SUM(I8:I18) -> 28060 | J6: =SUM(J8:J18) -> 0 | K6: =SUM(K8:K18) -> 56789 | ... N6: =SUM(N8:N18) -> 472 | O6: =+D6/C6 -> 1.2371942
A7: Quang Ninh | E7: =SUM(F7:J7) -> 0
A8: Cái Lân (CICT) | E8: =SUM(F8:J8) -> 0
A9: Hai Phong (Chùa Vẽ+Tân Vũ) | B9: =715133+126685+111732+106510+95851+111311 -> 1267222 | C9: 715133 | D9: =108077+85467+113186+113042+116756+109995+110509 -> 757032 | E9: =SUM(F9:J9) -> 110509 | F9: 42495 | G9: 41826 | H9: 14421 | I9: 11767 | O9: =+D9/C9 -> 1.0585891
A10: HICT (Lạch Huyện, HP) | B10: 1272859 | C10: 625690 | D10: =148719+103732+138638+114388+149772+144287+154524 -> 954060 | E10: =SUM(F10:J10) -> 154524 | F10: 77132 | G10: 77392 | K10: =9775+7952 -> 17727 | L10: =1569+652 -> 2221 | O10: =+D10/C10 -> 1.5248126
A11: Đoạn Xá | E11: =SUM(F11:J11) -> 0
A12: Đình vũ | B12: 491959 | C12: 281902 | D12: =39231+38035+45839+55212+55252+51874+53719 -> 339162 | E12: =SUM(F12:J12) -> 53719 | F12: 27222 | G12: 24183 | H12: 1028 | I12: 1286 | K12: =8014+3619+203+386 -> 12222 | L12: =72+3866+127+38 -> 4103 | O12: =+D12/C12 -> 1.2031202
A13: Nam Hải Đình Vũ | B13: 149160 | C13: 149160 | D13: 0 | E13: =SUM(F13:J13) -> 0 | O13: =+D13/C13 -> 0
A14: Nam Đình Vũ | B14: =27700+42263+60649+60306+68982+89333+103549+96251+80177+83538+83985+100491 -> 897224 | C14: 452782 | D14: =107401+71667+97692+112321+100543+91682+100061 -> 681367 | E14: =SUM(F14:J14) -> 100061 | F14: 49644 | G14: 50417 | K14: =10447+8710 -> 19157 | L14: =553+2789 -> 3342 | N14: 472 | O14: =+D14/C14 -> 1.5048456
A15: Tân Cảng 128 Hải Phòng | B15: =6147+7479+7850+9613+8350+10297+8331+8950+9929+9191+7491+7125 -> 100753 | C15: 58067 | D15: =5818+3471+4879+3146+1868+3203+3535 -> 25920 | E15: =SUM(F15:J15) -> 3535 | H15: 1793 | I15: 1742 | K15: 789 | L15: 460 | O15: =+D15/C15 -> 0.4463809
A16: Transvina | B16: =540+350 -> 890 | D16: =528 -> 528 | E16: 0
A17: PTSC Đình Vũ | B17: =14801+21013+19343+20052+25339+15490+23521+25450+24091+25115+25902+30182 -> 270299 | C17: 139559 | D17: =29509+14652+23209+24242+23009+26529+25218 -> 166368 | E17: =SUM(F17:J17) -> 25218 | H17: 11953 | I17: 13265 | K17: 6894 | L17: =1127+1311 -> 2438 | O17: =+D17/C17 -> 1.192098
A18: VIMC Đình Vũ | B18: 67816 | C18: 13513 | D18: =63204+12868+13056 -> 89128 | E18: 13056 | O18: =+D18/C18 -> 6.5957226
A19: Vip Green Port (*) | B19: 633659 | C19: 311094 | D19: 390003 | E19: 61407
A20: Green Port (*) | B20: 255481 | C20: 131237 | D20: =86240+22448+23244+20269 -> 152201 | E20: 20269
A21: Mipec (*) | B21: 92242 | C21: 65671 | D21: =15392+5518+8672+12966+12436 -> 54984 | E21: 12436
A22: Hải An (*) | B22: 400078 | C22: 181482 | D22: =36183+30507+38929+42926+38815+41506+38762 -> 267628 | E22: 38762
A23: TC 189 Hải Phòng (*) | B23: 171077 | C23: 86011 | D23: =60794+15126+16149+16947 -> 109016 | E23: 16947
A24: Nam Hải Dình Vũ (*) | B24: 270677 | C24: 167757 | D24: =22071+9654+13100+21751+25961+15202+11637 -> 119376 | E24: 11637
A25: Nam Hải | D25: =3457+12735+18119+18316+19560 -> 72187 | E25: 19560
B26: =SUM(B19:B25) -> 1823214 | C26: =SUM(C19:C25) -> 943252 | D26: =SUM(D19:D25) -> 1165395 | E26: =SUM(E19:E25) -> 181018
A28: MIỀN TRUNG | B28: =SUM(B29:B32) -> 860026 | C28: 479005 | D28: =SUM(D29:D32) -> 559117 | E28: =SUM(E29:E32) -> 82417 | F28: =SUM(F29:F32) -> 29221 | G28: =SUM(G29:G32) -> 31414 | H28: =SUM(H29:H32) -> 10528 | I28: =SUM(I29:I32) -> 11254 | J28: =SUM(J29:J32) -> 0 | K28: =SUM(K29:K32) -> 13426 | L28: =SUM(L29:L32) -> 3244 | M28: 0 | N28: =SUM(N29:N32) -> 0 | O28: =+D28/C28 -> 1.1672467
A29: Nghe Tinh | B29: =30481+3346 -> 33827 | C29: 18703 | D29: =4188+2189+2953+3363+3389+2628+3750 -> 22460 | E29: =SUM(F29:J29) -> 3758 | H29: 1844 | I29: 1914 | K29: =546+878 -> 1424 | L29: =282+878 -> 1160 | O29: =+D29/C29 -> 1.2008769
A30: Da Nang | B30: 675254 | C30: 370809 | D30: =64505+48073+62185+62452+59765+64280+67096 -> 428356 | E30: =SUM(F30:J30) -> 67096 | F30: 23914 | G30: 26196 | H30: 7847 | I30: 9139 | K30: =4065+4787+1953+1197 -> 12002 | L30: =517+569+506+492 -> 2084 | M30: 0 | N30: 0 | O30: =+D30/C30 -> 1.1551931
A31: Quy Nhon | B31: =120488+12239+18218 -> 150945 | C31: =89493+11563 -> 101056 | D31: =22490+11900+19473+16591+12914+13370+11563 -> 108301 | E31: =SUM(F31:J31) -> 11563 | F31: 5307 | G31: 5218 | H31: 837 | I31: 201 | O31: =+D31/C31 -> 1.0716929
A32: Cam Ranh | B32: 0 | C32: 0
A34: TP HCM | B34: =SUM(B35:B45) -> 8314054 | C34: 4679787 | D34: =SUM(D35:D45) -> 5204286 | E34: =SUM(E35:E45) -> 794644 | F34: =SUM(F35:F45) -> 312592 | G34: =SUM(G35:G45) -> 254118 | H34: =SUM(H35:H45) -> 94831 | I34: =SUM(I35:I45) -> 131680 | J34: =SUM(J35:J45) -> 1423 | K34: =SUM(K35:K45) -> 175258 | ... N34: =SUM(N35:N45) -> 61241 | O34: =+D34/C34 -> 1.1120775
A35: Binh Duong | B35: =439746+58130+61049 -> 558925 | C35: 298937 | D35: =176793+71526+59980+65204+71423 -> 444926 | E35: =SUM(F35:J35) -> 71423 | H35: 17792 | I35: 53631 | K35: 2561 | L35: =13428 -> 13428 | O35: =+D35/C35 -> 1.4883604
A36: Đồng Nai | B36: =506252+63971 -> 570223 | C36: 297583 | D36: =315296+56739 -> 372035 | E36: =SUM(F36:J36) -> 56739 | H36: 9484 | I36: 47255 | K36: 1187 | L36: =9178 -> 9178 | N36: 56739 | O36: =+D36/C36 -> 1.250189
A37: ITC- CORP | B37: =42017+51282+45948+47390+55304+49234+45680+47437+43911+34616+30188+41910 -> 534917 | C37: 338855 | D37: =43919+38655+49389+49920+41452+46211+54147 -> 323693 | E37: =SUM(F37:J37) -> 54147 | F37: 21058 | G37: 19986 | H37: 5222 | I37: 6458 | J37: 1423 | K37: =3651+4957+1467+846+31 -> 10952 | L37: =967+317+1+594+72 -> 1951 | N37: 2678 | O37: =+D37/C37 -> 0.9552552
A38: Cảng Sai Gòn | B38: =154869+18461+17185+18184+22072 -> 230771 | C38: 121091 | D38: =20214+11681+23581+25619+22301+21824+20127 -> 145347 | E38: =SUM(F38:J38) -> 20127 | G38: 10 | H38: 10060 | I38: 10057 | K38: =2730+1961 -> 4691 | L38: =262+968 -> 1230 | M38: 294 | O38: =+D38/C38 -> 1.2003122
A39: Ben Nghe | B39: =50925+32855+32535+28886+28236+30552+33558+32390+29858+33841+31383 -> 365019 | C39: 203989 | D39: =36191+20920+29070+23929+27875+30427+28473 -> 196885 | E39: =SUM(H39:J39) -> 28473 | H39: 14194 | I39: 14279 | K39: =4806+4299 -> 9105 | L39: =72+544 -> 616 | N39: 0 | O39: =+D39/C39 -> 0.96517459
A40: Tan Cang - Hiệp Phước | B40: =5696+3958+5815+9110+7468+13154+12856+16704+16494+13524+11707+13991 -> 130477 | C40: 58057 | D40: =12008+9467+14763+14113+14691+14606+10209 -> 89857 | E40: =SUM(F40:J40) -> 10209 | F40: 2614 | G40: 7595 | K40: =918+1269 -> 2187 | L40: =18+1280 -> 1298 | O40: =+D40/C40 -> 1.5477376
A41: Tan Cang - Cat Lai | B41: =372397+393542+480876+438506+433683+444706+469051+460647+432596+460939+470477+474708 -> 5332128 | C41: 3032761 | D41: =492323+373517+489518+501319+498148+483300+509517 -> 3347642 | E41: =SUM(F41:J41) -> 509517 | F41: 284281 | G41: 225236 | K41: =77370+66737 -> 144107 | L41: =4051+12109 -> 16160 | O41: =+D41/C41 -> 1.1038265
A42: VICT | B42: =32440+39588+48102+43548+41412+40968+51704+51435+55440+57617+45700+41689 -> 549643 | C42: 297762 | D42: =41444+27037+39698+37856+42480+38521+41958 -> 268994 | E42: =SUM(F42:J42) -> 41958 | F42: 3879 | H42: 38079 | O42: =+D42/C42 -> 0.90338593
A43: SPCT | B43: =SUM(D43:G43) -> 0
A44: Lotus | B44: =2388+2166+2181+2143+2735+2159+2232+3124+2401+2891+2264+3229 -> 29913 | C44: 16004 | D44: =1591+185+300+228+282+250+254 -> 3090 | E44: =SUM(F44:J44) -> 254 | F44: 94 | G44: 160 | K44: 254 | L44: =94 -> 94 | N44: 27 | O44: =+D44/C44 -> 0.19307673
...

Sheet T08-2024
A1: VPA - SẢN LƯỢNG CONTAINER (TEU) - THÁNG 8 NĂM 2024 / 2023
A3: KHU VỰC / Cảng | B3: Năm 2023 | C3: 8T2023 | D3: 8T 2024 | E3: THÁNG 8-2024 | O3: 8T (2024 / 2023)
E4: CỘNG | F4: Nhập Ngoại | G4: Xuất Ngoại | H4: Nhập nội | I4: Xuất nội | J4: Trung chuyển | K4: 20' | L4: Rỗng | M4: Lạnh | N4: GN qua sà lan
A6: MIỀN BẮC | B6: =SUM(B8:B18) -> 4518182 | C6: 2849439 | D6: =SUM(D8:D18) -> 3490608 | E6: =SUM(E8:E18) -> 477043 | F6: =SUM(F8:F18) -> 206530 | G6: =SUM(G8:G18) -> 202023 | H6: =SUM(H8:H18) -> 29934 | I6: =SUM(I8:I18) -> 26317 | J6: =SUM(J8:J18) -> 0 | K6: =SUM(K8:K18) -> 61829 | ... N6: =SUM(N8:N18) -> 266 | O6: =+D6/C6 -> 1.2250159
A7: Quang Ninh | E7: =SUM(F7:J7) -> 0
A8: Cái Lân (CICT) | E8: =SUM(F8:J8) -> 0
A9: Hai Phong (Chùa Vẽ+Tân Vũ) | B9: =715133+126685+111732+106510+95851+111311 -> 1267222 | C9: 841818 | D9: =108077+85467+113186+113042+116756+109995+110509+101300 -> 858332 | E9: =SUM(F9:J9) -> 101300 | F9: 37566 | G9: 39547 | H9: 12851 | I9: 11336 | O9: =+D9/C9 -> 1.0196171
A10: HICT (Lạch Huyện, HP) | B10: 1272859 | C10: 727980 | D10: =148719+103732+138638+114388+149772+144287+154524+162231 -> 1116291 | E10: =SUM(F10:J10) -> 162231 | F10: 82431 | G10: 79800 | K10: =8134+7701 -> 15835 | L10: =1629+843 -> 2472 | O10: =+D10/C10 -> 1.5334089
A11: Đoạn Xá | E11: =SUM(F11:J11) -> 0
A12: Đình vũ | B12: 491959 | C12: 327428 | D12: =39231+38035+45839+55212+55252+51874+53719+51193 -> 390355 | E12: =SUM(F12:J12) -> 51193 | F12: 24012 | G12: 25787 | H12: 1128 | I12: 266 | K12: =7678+3348+57+151 -> 11234 | L12: =36+5429+71+5 -> 5541 | O12: =+D12/C12 -> 1.1921858
A13: Nam Hải Đình Vũ | B13: 149160 | C13: 149160 | D13: 0 | O13: =+D13/C13 -> 0
A14: Nam Đình Vũ | B14: =27700+42263+60649+60306+68982+89333+103549+96251+80177+83538+83985+100491 -> 897224 | C14: 549033 | D14: =107401+71667+97692+112321+100543+91682+100061+119410 -> 800777 | E14: =SUM(F14:J14) -> 119410 | F14: 62521 | G14: 56889 | K14: 26682 | L14: =12660+9915 -> 22575 | M14: 6269 | N14: 266 | O14: =+D14/C14 -> 1.4585225
A15: Tân Cảng 128 Hải Phòng | B15: =6147+7479+7850+9613+8350+10297+8331+8950+9929+9191+7491+7125 -> 100753 | C15: 67017 | D15: =5818+3471+4879+3146+1868+3203+3535+2520 -> 28440 | E15: =SUM(F15:J15) -> 2520 | H15: 1401 | I15: 1119 | K15: =270+206 -> 476 | L15: =21+129 -> 150 | O15: =+D15/C15 -> 0.42436994
A16: Transvina | B16: =540+350 -> 890 | C16: 540 | D16: =528 -> 528 | E16: 0 | O16: =+D16/C16 -> 0.97777778
A17: PTSC Đình Vũ | B17: =14801+21013+19343+20052+25339+15490+23521+25450+24091+25115+25902+30182 -> 270299 | C17: 165009 | D17: =29509+14652+23209+24242+23009+26529+25218+28150 -> 194518 | E17: =SUM(F17:J17) -> 28150 | H17: 14554 | I17: 13596 | K17: 7602 | L17: =2249+1180 -> 3429 | O17: =+D17/C17 -> 1.1788327
A18: VIMC Đình Vũ / cập nhật | B18: 67816 | C18: 21454 | D18: =63204+12868+13056+12239 -> 101367 | E18: 12239 | O18: =+D18/C18 -> 4.7248532
A19: Vip Green Port (*) | B19: 633659 | C19: 415433 | D19: 450966 | E19: 60953
A20: Green Port (*) | B20: 255481 | C20: 172607 | D20: 185932 | E20: 33731
A21: Mipec (*) | B21: 92242 | C21: 80197 | D21: 68446 | E21: 13462
A22: Hải An (*) | B22: 400078 | C22: 251716 | D22: 300953 | E22: 33325
A23: TC 189 Hải Phòng (*) | B23: 171077 | C23: 110930 | D23: 123245 | E23: 14229
A24: Nam Hải Dình Vũ (*) | B24: 270677 | C24: 206371 | D24: 137928 | E24: 18552
A25: Nam Hải | D25: 89439 | E25: 17252
B26: =SUM(B19:B25) -> 1823214 | C26: 1237254 | D26: =SUM(D19:D25) -> 1356909 | E26: =SUM(E19:E25) -> 191504
A28: MIỀN TRUNG | B28: =SUM(B29:B32) -> 860026 | C28: 550927 | D28: =SUM(D29:D32) -> 643020 | E28: =SUM(E29:E32) -> 83903 | F28: =SUM(F29:F32) -> 34700 | G28: =SUM(G29:G32) -> 29853 | H28: =SUM(H29:H32) -> 9607 | I28: =SUM(I29:I32) -> 9743 | J28: =SUM(J29:J32) -> 0 | K28: =SUM(K29:K32) -> 16360 | L28: =SUM(L29:L32) -> 13497 | M28: 0 | N28: =SUM(N29:N32) -> 0 | O28: =+D28/C28 -> 1.1671601
A29: Nghe Tinh | B29: =30481+3346 -> 33827 | C29: 21603 | D29: =4188+2189+2953+3363+3389+2628+3750+3460 -> 25920 | E29: =SUM(F29:J29) -> 3460 | H29: 1769 | I29: 1691 | K29: =721+798 -> 1519 | L29: =212+2 -> 214 | O29: =+D29/C29 -> 1.1998334
A30: Da Nang | B30: 675254 | C30: 429974 | D30: =64505+48073+62185+62452+59765+64280+67096+71165 -> 499521 | E30: =SUM(F30:J30) -> 71165 | F30: 30665 | G30: 25526 | H30: 7169 | I30: 7805 | K30: 13821 | L30: =2599+2940+1583+5557 -> 12679 | O30: =+D30/C30 -> 1.161747
A31: Quy Nhon | B31: =120488+12239+18218 -> 150945 | C31: 99350 | D31: =22490+11900+19473+16591+12914+13370+11563+9278 -> 117579 | E31: =SUM(F31:J31) -> 9278 | F31: 4035 | G31: 4327 | H31: 669 | I31: 247 | K31: =247+602+108+63 -> 1020 | L31: =514+13+67+10 -> 604 | O31: =+D31/C31 -> 1.1834826
A32: Cam Ranh | B32: 0
